Workbook

Sheet 2015
B2: 예수금 | C2: 총평가금액 | D2: 원금 | E2: 대출금
B3: =C3-E16 -> 0 | C3: =D3+E3 -> 0
B5: 종목명 | C5: 주가 | D5: 주식수 | E5: 총매입
B6: A 엔터 | C6: =종목!C3 -> 49700 | E6: =C6*D6 -> 0
B7: B 여행 | C7: =종목!H3 -> 60500 | E7: =C7*D7 -> 0
B8: C IT | C8: =종목!M3 -> 39300 | E8: =C8*D8 -> 0
B9: D 바이오 | C9: =종목!C16 -> 35000 | E9: =C9*D9 -> 0
B10: E 자동차 | C10: =종목!H16 -> 123000 | E10: =C10*D10 -> 0
B11: F 통신 | C11: =종목!M16 -> 42800 | E11: =C11*D11 -> 0
B12: G 조선 | C12: =종목!C29 -> 80600 | E12: =C12*D12 -> 0
B13: H 뷰티 | C13: =종목!H29 -> 1066000 | E13: =C13*D13 -> 0
B14: I 화학 | C14: =종목!M29 -> 305000 | E14: =C14*D14 -> 0
B15: J 식품 | C15: =종목!C42 -> 120500 | E15: =C15*D15 -> 0
B16: 합계 | E16: =SUM(E6:E15) -> 0

Sheet 2016
B2: 대출금 | I2: 예수금 | J2: 총매도금액 | K2: 총매수금액 | L2: 총평가금액 | M2: 작년대비
I3: =L3-M16 -> 0 | J3: =K16 -> 0 | K3: =L16 -> 0 | L3: ='2015'!C3+'2016'!E16+B3 -> 0 | M3: =(L3-'2015'!C3)/'2016'!L3 -> #DIV/0!
B5: 종목명 | C5: 주가 | D5: 주식수 | E5: 평가금액 | F5: 현재주가 | G5: 수익률 | I5: 종목명 | J5: 주가 | K5: 매도 | L5: 매수 | M5: 주식수
B6: A 엔터 | C6: ='2015'!C6 -> 49700 | D6: ='2015'!D6 -> 0 | E6: =(F6*D6)-(C6*D6) -> 0 | F6: =종목!C4 -> 23800 | G6: =(F6-C6)/C6 -> -0.52112676 | I6: A 엔터 | J6: =F6 -> 23800 | M6: =(D6-K6)+L6 -> 0
B7: B 여행 | C7: ='2015'!C7 -> 60500 | D7: ='2015'!D7 -> 0 | E7: =(F7*D7)-(C7*D7) -> 0 | F7: =종목!H4 -> 205000 | G7: =(F7-C7)/C7 -> 2.3884298 | I7: B 여행 | J7: =F7 -> 205000 | M7: =(D7-K7)+L7 -> 0
B8: C IT | C8: ='2015'!C8 -> 39300 | D8: ='2015'!D8 -> 0 | E8: =(F8*D8)-(C8*D8) -> 0 | F8: =종목!M4 -> 44700 | G8: =(F8-C8)/C8 -> 0.13740458 | I8: C IT | J8: =F8 -> 44700 | M8: =(D8-K8)+L8 -> 0
B9: D 바이오 | C9: ='2015'!C9 -> 35000 | D9: ='2015'!D9 -> 0 | E9: =(F9*D9)-(C9*D9) -> 0 | F9: =종목!C17 -> 108000 | G9: =(F9-C9)/C9 -> 2.0857143 | I9: D 바이오 | J9: =F9 -> 108000 | M9: =(D9-K9)+L9 -> 0
B10: E 자동차 | C10: ='2015'!C10 -> 123000 | D10: ='2015'!D10 -> 0 | E10: =(F10*D10)-(C10*D10) -> 0 | F10: =종목!H17 -> 126500 | G10: =(F10-C10)/C10 -> 0.028455285 | I10: E 자동차 | J10: =F10 -> 126500 | M10: =(D10-K10)+L10 -> 0
B11: F 통신 | C11: ='2015'!C11 -> 42800 | D11: ='2015'!D11 -> 0 | E11: =(F11*D11)-(C11*D11) -> 0 | F11: =종목!M17 -> 38300 | G11: =(F11-C11)/C11 -> -0.10514019 | I11: F 통신 | J11: =F11 -> 38300 | M11: =(D11-K11)+L11 -> 0
B12: G 조선 | C12: ='2015'!C12 -> 80600 | D12: ='2015'!D12 -> 0 | E12: =(F12*D12)-(C12*D12) -> 0 | F12: =종목!C30 -> 166000 | G12: =(F12-C12)/C12 -> 1.0595533 | I12: G 조선 | J12: =F12 -> 166000 | M12: =(D12-K12)+L12 -> 0
B13: H 뷰티 | C13: ='2015'!C13 -> 1066000 | D13: ='2015'!D13 -> 0 | E13: =(F13*D13)-(C13*D13) -> 0 | F13: =종목!H30 -> 740000 | G13: =(F13-C13)/C13 -> -0.30581614 | I13: H 뷰티 | J13: =F13 -> 740000 | M13: =(D13-K13)+L13 -> 0
B14: I 화학 | C14: ='2015'!C14 -> 305000 | D14: ='2015'!D14 -> 0 | E14: =(F14*D14)-(C14*D14) -> 0 | F14: =종목!M30 -> 370000 | G14: =(F14-C14)/C14 -> 0.21311475 | I14: I 화학 | J14: =F14 -> 370000 | M14: =(D14-K14)+L14 -> 0
B15: J 식품 | C15: ='2015'!C15 -> 120500 | D15: ='2015'!D15 -> 0 | E15: =(F15*D15)-(C15*D15) -> 0 | F15: =종목!C43 -> 139500 | G15: =(F15-C15)/C15 -> 0.15767635 | I15: J 식품 | J15: =F15 -> 139500 | M15: =(D15-K15)+L15 -> 0
B16: 합계 | E16: =SUM(E6:E15) -> 0 | I16: 합계 | K16: =(J6*K6)+(J7*K7)+(J8*K8)+(J9*K9)+(J10*K10)+(J11*K11)+(J12*K12)+(J13*K13)+(J14*K14)+(J15*K15) -> 0 | L16: =(J6*L6)+(J7*L7)+(J8*L8)+(J9*L9)+(J10*L10)+(J11*L11)+(J12*L12)+(J13*L13)+(J14*L14)+(J15*L15) -> 0 | M16: =J6*M6+J7*M7+J8*M8+J9*M9+J10*M10+J11*M11+J12*M12+J13*M13+J14*M14+J15*M15 -> 0

Sheet 2017
B2: 대출금 | I2: 예수금 | J2: 총매도금액 | K2: 총매수금액 | L2: 총평가금액 | M2: 작년대비
I3: =L3-M16 -> 0 | J3: =K16 -> 0 | K3: =L16 -> 0 | L3: ='2016'!L3+'2017'!E16+B3 -> 0 | M3: =(L3-'2015'!C3)/'2017'!L3 -> #DIV/0!
B5: 종목명 | C5: 주가 | D5: 주식수 | E5: 평가금액 | F5: 현재주가 | G5: 수익률 | I5: 종목명 | J5: 주가 | K5: 매도 | L5: 매수 | M5: 주식수
B6: A 엔터 | C6: ='2016'!J6 -> 23800 | D6: ='2016'!M6 -> 0 | E6: =(F6*D6)-(C6*D6) -> 0 | F6: =종목!C5 -> 39150 | G6: =(F6-C6)/C6 -> 0.64495798 | I6: A 엔터 | J6: =F6 -> 39150 | M6: =(D6-K6)+L6 -> 0
B7: B 여행 | C7: ='2016'!J7 -> 205000 | D7: ='2016'!M7 -> 0 | E7: =(F7*D7)-(C7*D7) -> 0 | F7: =종목!H5 -> 62500 | G7: =(F7-C7)/C7 -> -0.69512195 | I7: B 여행 | J7: =F7 -> 62500 | M7: =(D7-K7)+L7 -> 0
B8: C IT | C8: ='2016'!J8 -> 44700 | D8: ='2016'!M8 -> 0 | E8: =(F8*D8)-(C8*D8) -> 0 | F8: =종목!M5 -> 109500 | G8: =(F8-C8)/C8 -> 1.4496644 | I8: C IT | J8: =F8 -> 109500 | M8: =(D8-K8)+L8 -> 0
B9: D 바이오 | C9: ='2016'!J9 -> 108000 | D9: ='2016'!M9 -> 0 | E9: =(F9*D9)-(C9*D9) -> 0 | F9: =종목!C18 -> 196000 | G9: =(F9-C9)/C9 -> 0.81481481 | I9: D 바이오 | J9: =F9 -> 196000 | M9: =(D9-K9)+L9 -> 0
B10: E 자동차 | C10: ='2016'!J10 -> 126500 | D10: ='2016'!M10 -> 0 | E10: =(F10*D10)-(C10*D10) -> 0 | F10: =종목!H18 -> 133000 | G10: =(F10-C10)/C10 -> 0.051383399 | I10: E 자동차 | J10: =F10 -> 133000 | M10: =(D10-K10)+L10 -> 0
B11: F 통신 | C11: ='2016'!J11 -> 38300 | D11: ='2016'!M11 -> 0 | E11: =(F11*D11)-(C11*D11) -> 0 | F11: =종목!M18 -> 57600 | G11: =(F11-C11)/C11 -> 0.50391645 | I11: F 통신 | J11: =F11 -> 57600 | M11: =(D11-K11)+L11 -> 0
B12: G 조선 | C12: ='2016'!J12 -> 166000 | D12: ='2016'!M12 -> 0 | E12: =(F12*D12)-(C12*D12) -> 0 | F12: =종목!C31 -> 187500 | G12: =(F12-C12)/C12 -> 0.12951807 | I12: G 조선 | J12: =F12 -> 187500 | M12: =(D12-K12)+L12 -> 0
B13: H 뷰티 | C13: ='2016'!J13 -> 740000 | D13: ='2016'!M13 -> 0 | E13: =(F13*D13)-(C13*D13) -> 0 | F13: =종목!H31 -> 774000 | G13: =(F13-C13)/C13 -> 0.045945946 | I13: H 뷰티 | J13: =F13 -> 774000 | M13: =(D13-K13)+L13 -> 0
B14: I 화학 | C14: ='2016'!J14 -> 370000 | D14: ='2016'!M14 -> 0 | E14: =(F14*D14)-(C14*D14) -> 0 | F14: =종목!M31 -> 422000 | G14: =(F14-C14)/C14 -> 0.14054054 | I14: I 화학 | J14: =F14 -> 422000 | M14: =(D14-K14)+L14 -> 0
B15: J 식품 | C15: ='2016'!J15 -> 139500 | D15: ='2016'!M15 -> 0 | E15: =(F15*D15)-(C15*D15) -> 0 | F15: =종목!C44 -> 94900 | G15: =(F15-C15)/C15 -> -0.31971326 | I15: J 식품 | J15: =F15 -> 94900 | M15: =(D15-K15)+L15 -> 0
B16: 합계 | E16: =SUM(E6:E15) -> 0 | I16: 합계 | K16: =(J6*K6)+(J7*K7)+(J8*K8)+(J9*K9)+(J10*K10)+(J11*K11)+(J12*K12)+(J13*K13)+(J14*K14)+(J15*K15) -> 0 | L16: =(J6*L6)+(J7*L7)+(J8*L8)+(J9*L9)+(J10*L10)+(J11*L11)+(J12*L12)+(J13*L13)+(J14*L14)+(J15*L15) -> 0 | M16: =J6*M6+J7*M7+J8*M8+J9*M9+J10*M10+J11*M11+J12*M12+J13*M13+J14*M14+J15*M15 -> 0

Sheet 2018
B2: 대출금 | I2: 예수금 | J2: 총매도금액 | K2: 총매수금액 | L2: 총평가금액 | M2: 작년대비
I3: =L3-M16 -> 0 | J3: =K16 -> 0 | K3: =L16 -> 0 | L3: ='2017'!L3+'2018'!E16+B3 -> 0 | M3: =(L3-'2015'!C3)/'2018'!L3 -> #DIV/0!
B5: 종목명 | C5: 주가 | D5: 주식수 | E5: 평가금액 | F5: 현재주가 | G5: 수익률 | I5: 종목명 | J5: 주가 | K5: 매도 | L5: 매수 | M5: 주식수
B6: A 엔터 | C6: ='2017'!J6 -> 39150 | D6: ='2017'!M6 -> 0 | E6: =(F6*D6)-(C6*D6) -> 0 | F6: =종목!C6 -> 156900 | G6: =(F6-C6)/C6 -> 3.0076628 | I6: A 엔터 | J6: =F6 -> 156900 | M6: =(D6-K6)+L6 -> 0
B7: B 여행 | C7: ='2017'!J7 -> 62500 | D7: ='2017'!M7 -> 0 | E7: =(F7*D7)-(C7*D7) -> 0 | F7: =종목!H6 -> 55900 | G7: =(F7-C7)/C7 -> -0.1056 | I7: B 여행 | J7: =F7 -> 55900 | M7: =(D7-K7)+L7 -> 0
B8: C IT | C8: ='2017'!J8 -> 109500 | D8: ='2017'!M8 -> 0 | E8: =(F8*D8)-(C8*D8) -> 0 | F8: =종목!M6 -> 58800 | G8: =(F8-C8)/C8 -> -0.4630137 | I8: C IT | J8: =F8 -> 58800 | M8: =(D8-K8)+L8 -> 0
B9: D 바이오 | C9: ='2017'!J9 -> 196000 | D9: ='2017'!M9 -> 0 | E9: =(F9*D9)-(C9*D9) -> 0 | F9: =종목!C19 -> 374000 | G9: =(F9-C9)/C9 -> 0.90816327 | I9: D 바이오 | J9: =F9 -> 374000 | M9: =(D9-K9)+L9 -> 0
B10: E 자동차 | C10: ='2017'!J10 -> 133000 | D10: ='2017'!M10 -> 0 | E10: =(F10*D10)-(C10*D10) -> 0 | F10: =종목!H19 -> 92500 | G10: =(F10-C10)/C10 -> -0.30451128 | I10: E 자동차 | J10: =F10 -> 92500 | M10: =(D10-K10)+L10 -> 0
B11: F 통신 | C11: ='2017'!J11 -> 57600 | D11: ='2017'!M11 -> 0 | E11: =(F11*D11)-(C11*D11) -> 0 | F11: =종목!M19 -> 58200 | G11: =(F11-C11)/C11 -> 0.010416667 | I11: F 통신 | J11: =F11 -> 58200 | M11: =(D11-K11)+L11 -> 0
B12: G 조선 | C12: ='2017'!J12 -> 187500 | D12: ='2017'!M12 -> 0 | E12: =(F12*D12)-(C12*D12) -> 0 | F12: =종목!C32 -> 93700 | G12: =(F12-C12)/C12 -> -0.50026667 | I12: G 조선 | J12: =F12 -> 93700 | M12: =(D12-K12)+L12 -> 0
B13: H 뷰티 | C13: ='2017'!J13 -> 774000 | D13: ='2017'!M13 -> 0 | E13: =(F13*D13)-(C13*D13) -> 0 | F13: =종목!H32 -> 1010000 | G13: =(F13-C13)/C13 -> 0.30490956 | I13: H 뷰티 | J13: =F13 -> 1010000 | M13: =(D13-K13)+L13 -> 0
B14: I 화학 | C14: ='2017'!J14 -> 422000 | D14: ='2017'!M14 -> 0 | E14: =(F14*D14)-(C14*D14) -> 0 | F14: =종목!M32 -> 247000 | G14: =(F14-C14)/C14 -> -0.41469194 | I14: I 화학 | J14: =F14 -> 247000 | M14: =(D14-K14)+L14 -> 0
B15: J 식품 | C15: ='2017'!J15 -> 94900 | D15: ='2017'!M15 -> 0 | E15: =(F15*D15)-(C15*D15) -> 0 | F15: =종목!C45 -> 95500 | G15: =(F15-C15)/C15 -> 0.0063224447 | I15: J 식품 | J15: =F15 -> 95500 | M15: =(D15-K15)+L15 -> 0
B16: 합계 | E16: =SUM(E6:E15) -> 0 | I16: 합계 | K16: =(J6*K6)+(J7*K7)+(J8*K8)+(J9*K9)+(J10*K10)+(J11*K11)+(J12*K12)+(J13*K13)+(J14*K14)+(J15*K15) -> 0 | L16: =(J6*L6)+(J7*L7)+(J8*L8)+(J9*L9)+(J10*L10)+(J11*L11)+(J12*L12)+(J13*L13)+(J14*L14)+(J15*L15) -> 0 | M16: =J6*M6+J7*M7+J8*M8+J9*M9+J10*M10+J11*M11+J12*M12+J13*M13+J14*M14+J15*M15 -> 0

Sheet 2019
B2: 대출금 | I2: 예수금 | J2: 총매도금액 | K2: 총매수금액 | L2: 총평가금액 | M2: 작년대비
I3: =L3-M16 -> 0 | J3: =K16 -> 0 | K3: =L16 -> 0 | L3: ='2018'!L3+'2019'!E16+B3 -> 0 | M3: =(L3-'2015'!C3)/'2019'!L3 -> #DIV/0!
B5: 종목명 | C5: 주가 | D5: 주식수 | E5: 평가금액 | F5: 현재주가 | G5: 수익률 | I5: 종목명 | J5: 주가 | K5: 매도 | L5: 매수 | M5: 주식수
B6: A 엔터 | C6: ='2018'!J6 -> 156900 | D6: ='2018'!M6 -> 0 | E6: =(F6*D6)-(C6*D6) -> 0 | F6: =종목!C7 -> 27000 | G6: =(F6-C6)/C6 -> -0.82791587 | I6: A 엔터 | J6: =F6 -> 27000 | M6: =(D6-K6)+L6 -> 0
B7: B 여행 | C7: ='2018'!J7 -> 55900 | D7: ='2018'!M7 -> 0 | E7: =(F7*D7)-(C7*D7) -> 0 | F7: =종목!H7 -> 76400 | G7: =(F7-C7)/C7 -> 0.3667263 | I7: B 여행 | J7: =F7 -> 76400 | M7: =(D7-K7)+L7 -> 0
B8: C IT | C8: ='2018'!J8 -> 58800 | D8: ='2018'!M8 -> 0 | E8: =(F8*D8)-(C8*D8) -> 0 | F8: =종목!M7 -> 58500 | G8: =(F8-C8)/C8 -> -0.0051020408 | I8: C IT | J8: =F8 -> 58500 | M8: =(D8-K8)+L8 -> 0
B9: D 바이오 | C9: ='2018'!J9 -> 374000 | D9: ='2018'!M9 -> 0 | E9: =(F9*D9)-(C9*D9) -> 0 | F9: =종목!C20 -> 125000 | G9: =(F9-C9)/C9 -> -0.6657754 | I9: D 바이오 | J9: =F9 -> 125000 | M9: =(D9-K9)+L9 -> 0
B10: E 자동차 | C10: ='2018'!J10 -> 92500 | D10: ='2018'!M10 -> 0 | E10: =(F10*D10)-(C10*D10) -> 0 | F10: =종목!H20 -> 143500 | G10: =(F10-C10)/C10 -> 0.55135135 | I10: E 자동차 | J10: =F10 -> 143500 | M10: =(D10-K10)+L10 -> 0
B11: F 통신 | C11: ='2018'!J11 -> 58200 | D11: ='2018'!M11 -> 0 | E11: =(F11*D11)-(C11*D11) -> 0 | F11: =종목!M20 -> 458000 | G11: =(F11-C11)/C11 -> 6.8694158 | I11: F 통신 | J11: =F11 -> 458000 | M11: =(D11-K11)+L11 -> 0
B12: G 조선 | C12: ='2018'!J12 -> 93700 | D12: ='2018'!M12 -> 0 | E12: =(F12*D12)-(C12*D12) -> 0 | F12: =종목!C33 -> 93800 | G12: =(F12-C12)/C12 -> 0.0010672359 | I12: G 조선 | J12: =F12 -> 93800 | M12: =(D12-K12)+L12 -> 0
B13: H 뷰티 | C13: ='2018'!J13 -> 1010000 | D13: ='2018'!M13 -> 0 | E13: =(F13*D13)-(C13*D13) -> 0 | F13: =종목!H33 -> 1466000 | G13: =(F13-C13)/C13 -> 0.45148515 | I13: H 뷰티 | J13: =F13 -> 1466000 | M13: =(D13-K13)+L13 -> 0
B14: I 화학 | C14: ='2018'!J14 -> 247000 | D14: ='2018'!M14 -> 0 | E14: =(F14*D14)-(C14*D14) -> 0 | F14: =종목!M33 -> 207500 | G14: =(F14-C14)/C14 -> -0.15991903 | I14: I 화학 | J14: =F14 -> 207500 | M14: =(D14-K14)+L14 -> 0
B15: J 식품 | C15: ='2018'!J15 -> 95500 | D15: ='2018'!M15 -> 0 | E15: =(F15*D15)-(C15*D15) -> 0 | F15: =종목!C46 -> 93700 | G15: =(F15-C15)/C15 -> -0.018848168 | I15: J 식품 | J15: =F15 -> 93700 | M15: =(D15-K15)+L15 -> 0
B16: 합계 | E16: =SUM(E6:E15) -> 0 | I16: 합계 | K16: =(J6*K6)+(J7*K7)+(J8*K8)+(J9*K9)+(J10*K10)+(J11*K11)+(J12*K12)+(J13*K13)+(J14*K14)+(J15*K15) -> 0 | L16: =(J6*L6)+(J7*L7)+(J8*L8)+(J9*L9)+(J10*L10)+(J11*L11)+(J12*L12)+(J13*L13)+(J14*L14)+(J15*L15) -> 0 | M16: =J6*M6+J7*M7+J8*M8+J9*M9+J10*M10+J11*M11+J12*M12+J13*M13+J14*M14+J15*M15 -> 0

Sheet 2020
B2: 대출금 | I2: 예수금 | J2: 총매도금액 | K2: 총매수금액 | L2: 총평가금액 | M2: 작년대비
I3: =L3-M16 -> 0 | J3: =K16 -> 0 | K3: =L16 -> 0 | L3: ='2019'!L3+'2020'!E16+B3 -> 0 | M3: =(L3-'2015'!C3)/'2020'!L3 -> #DIV/0!
B5: 종목명 | C5: 주가 | D5: 주식수 | E5: 평가금액 | F5: 현재주가 | G5: 수익률 | I5: 종목명 | J5: 주가 | K5: 매도 | L5: 매수 | M5: 주식수
B6: A 엔터 | C6: ='2019'!J6 -> 27000 | D6: ='2019'!M6 -> 0 | E6: =(F6*D6)-(C6*D6) -> 0 | F6: =종목!C8 -> 16350 | G6: =(F6-C6)/C6 -> -0.39444444 | I6: A 엔터 | J6: =F6 -> 16350 | M6: =(D6-K6)+L6 -> 0
B7: B 여행 | C7: ='2019'!J7 -> 76400 | D7: ='2019'!M7 -> 0 | E7: =(F7*D7)-(C7*D7) -> 0 | F7: =종목!H8 -> 26600 | G7: =(F7-C7)/C7 -> -0.65183246 | I7: B 여행 | J7: =F7 -> 26600 | M7: =(D7-K7)+L7 -> 0
B8: C IT | C8: ='2019'!J8 -> 58500 | D8: ='2019'!M8 -> 0 | E8: =(F8*D8)-(C8*D8) -> 0 | F8: =종목!M8 -> 236500 | G8: =(F8-C8)/C8 -> 3.042735 | I8: C IT | J8: =F8 -> 236500 | M8: =(D8-K8)+L8 -> 0
B9: D 바이오 | C9: ='2019'!J9 -> 125000 | D9: ='2019'!M9 -> 0 | E9: =(F9*D9)-(C9*D9) -> 0 | F9: =종목!C21 -> 565000 | G9: =(F9-C9)/C9 -> 3.52 | I9: D 바이오 | J9: =F9 -> 565000 | M9: =(D9-K9)+L9 -> 0
B10: E 자동차 | C10: ='2019'!J10 -> 143500 | D10: ='2019'!M10 -> 0 | E10: =(F10*D10)-(C10*D10) -> 0 | F10: =종목!H21 -> 199000 | G10: =(F10-C10)/C10 -> 0.38675958 | I10: E 자동차 | J10: =F10 -> 199000 | M10: =(D10-K10)+L10 -> 0
B11: F 통신 | C11: ='2019'!J11 -> 458000 | D11: ='2019'!M11 -> 0 | E11: =(F11*D11)-(C11*D11) -> 0 | F11: =종목!M21 -> 50300 | G11: =(F11-C11)/C11 -> -0.89017467 | I11: F 통신 | J11: =F11 -> 50300 | M11: =(D11-K11)+L11 -> 0
B12: G 조선 | C12: ='2019'!J12 -> 93800 | D12: ='2019'!M12 -> 0 | E12: =(F12*D12)-(C12*D12) -> 0 | F12: =종목!C34 -> 64200 | G12: =(F12-C12)/C12 -> -0.31556503 | I12: G 조선 | J12: =F12 -> 64200 | M12: =(D12-K12)+L12 -> 0
B13: H 뷰티 | C13: ='2019'!J13 -> 1466000 | D13: ='2019'!M13 -> 0 | E13: =(F13*D13)-(C13*D13) -> 0 | F13: =종목!H34 -> 3649000 | G13: =(F13-C13)/C13 -> 1.4890859 | I13: H 뷰티 | J13: =F13 -> 3649000 | M13: =(D13-K13)+L13 -> 0
B14: I 화학 | C14: ='2019'!J14 -> 207500 | D14: ='2019'!M14 -> 0 | E14: =(F14*D14)-(C14*D14) -> 0 | F14: =종목!M34 -> 114500 | G14: =(F14-C14)/C14 -> -0.44819277 | I14: I 화학 | J14: =F14 -> 114500 | M14: =(D14-K14)+L14 -> 0
B15: J 식품 | C15: ='2019'!J15 -> 93700 | D15: ='2019'!M15 -> 0 | E15: =(F15*D15)-(C15*D15) -> 0 | F15: =종목!C47 -> 98100 | G15: =(F15-C15)/C15 -> 0.046958378 | I15: J 식품 | J15: =F15 -> 98100 | M15: =(D15-K15)+L15 -> 0
B16: 합계 | E16: =SUM(E6:E15) -> 0 | I16: 합계 | K16: =(J6*K6)+(J7*K7)+(J8*K8)+(J9*K9)+(J10*K10)+(J11*K11)+(J12*K12)+(J13*K13)+(J14*K14)+(J15*K15) -> 0 | L16: =(J6*L6)+(J7*L7)+(J8*L8)+(J9*L9)+(J10*L10)+(J11*L11)+(J12*L12)+(J13*L13)+(J14*L14)+(J15*L15) -> 0 | M16: =J6*M6+J7*M7+J8*M8+J9*M9+J10*M10+J11*M11+J12*M12+J13*M13+J14*M14+J15*M15 -> 0

Sheet 2021
B2: 대출금 | I2: 예수금 | J2: 총매도금액 | K2: 총매수금액 | L2: 총평가금액 | M2: 작년대비
I3: =L3-M16 -> 0 | J3: =K16 -> 0 | K3: =L16 -> 0 | L3: ='2020'!L3+'2021'!E16+B3 -> 0 | M3: =(L3-'2015'!C3)/'2021'!L3 -> #DIV/0!
B5: 종목명 | C5: 주가 | D5: 주식수 | E5: 평가금액 | F5: 현재주가 | G5: 수익률 | I5: 종목명 | J5: 주가 | K5: 매도 | L5: 매수 | M5: 주식수
B6: A 엔터 | C6: ='2020'!J6 -> 16350 | D6: ='2020'!M6 -> 0 | E6: =(F6*D6)-(C6*D6) -> 0 | F6: =종목!C9 -> 85000 | G6: =(F6-C6)/C6 -> 4.1987768 | I6: A 엔터 | J6: =F6 -> 85000 | M6: =(D6-K6)+L6 -> 0
B7: B 여행 | C7: ='2020'!J7 -> 26600 | D7: ='2020'!M7 -> 0 | E7: =(F7*D7)-(C7*D7) -> 0 | F7: =종목!H9 -> 94300 | G7: =(F7-C7)/C7 -> 2.5451128 | I7: B 여행 | J7: =F7 -> 94300 | M7: =(D7-K7)+L7 -> 0
B8: C IT | C8: ='2020'!J8 -> 236500 | D8: ='2020'!M8 -> 0 | E8: =(F8*D8)-(C8*D8) -> 0 | F8: =종목!M9 -> 115000 | G8: =(F8-C8)/C8 -> -0.51374207 | I8: C IT | J8: =F8 -> 115000 | M8: =(D8-K8)+L8 -> 0
B9: D 바이오 | C9: ='2020'!J9 -> 565000 | D9: ='2020'!M9 -> 0 | E9: =(F9*D9)-(C9*D9) -> 0 | F9: =종목!C22 -> 185000 | G9: =(F9-C9)/C9 -> -0.67256637 | I9: D 바이오 | J9: =F9 -> 185000 | M9: =(D9-K9)+L9 -> 0
B10: E 자동차 | C10: ='2020'!J10 -> 199000 | D10: ='2020'!M10 -> 0 | E10: =(F10*D10)-(C10*D10) -> 0 | F10: =종목!H22 -> 289000 | G10: =(F10-C10)/C10 -> 0.45226131 | I10: E 자동차 | J10: =F10 -> 289000 | M10: =(D10-K10)+L10 -> 0
B11: F 통신 | C11: ='2020'!J11 -> 50300 | D11: ='2020'!M11 -> 0 | E11: =(F11*D11)-(C11*D11) -> 0 | F11: =종목!M22 -> 47000 | G11: =(F11-C11)/C11 -> -0.065606362 | I11: F 통신 | J11: =F11 -> 47000 | M11: =(D11-K11)+L11 -> 0
B12: G 조선 | C12: ='2020'!J12 -> 64200 | D12: ='2020'!M12 -> 0 | E12: =(F12*D12)-(C12*D12) -> 0 | F12: =종목!C35 -> 163500 | G12: =(F12-C12)/C12 -> 1.546729 | I12: G 조선 | J12: =F12 -> 163500 | M12: =(D12-K12)+L12 -> 0
B13: H 뷰티 | C13: ='2020'!J13 -> 3649000 | D13: ='2020'!M13 -> 0 | E13: =(F13*D13)-(C13*D13) -> 0 | F13: =종목!H35 -> 971000 | G13: =(F13-C13)/C13 -> -0.7338997 | I13: H 뷰티 | J13: =F13 -> 971000 | M13: =(D13-K13)+L13 -> 0
B14: I 화학 | C14: ='2020'!J14 -> 114500 | D14: ='2020'!M14 -> 0 | E14: =(F14*D14)-(C14*D14) -> 0 | F14: =종목!M35 -> 538000 | G14: =(F14-C14)/C14 -> 3.69869 | I14: I 화학 | J14: =F14 -> 538000 | M14: =(D14-K14)+L14 -> 0
B15: J 식품 | C15: ='2020'!J15 -> 98100 | D15: ='2020'!M15 -> 0 | E15: =(F15*D15)-(C15*D15) -> 0 | F15: =종목!C48 -> 78000 | G15: =(F15-C15)/C15 -> -0.20489297 | I15: J 식품 | J15: =F15 -> 78000 | M15: =(D15-K15)+L15 -> 0
B16: 합계 | E16: =SUM(E6:E15) -> 0 | I16: 합계 | K16: =(J6*K6)+(J7*K7)+(J8*K8)+(J9*K9)+(J10*K10)+(J11*K11)+(J12*K12)+(J13*K13)+(J14*K14)+(J15*K15) -> 0 | L16: =(J6*L6)+(J7*L7)+(J8*L8)+(J9*L9)+(J10*L10)+(J11*L11)+(J12*L12)+(J13*L13)+(J14*L14)+(J15*L15) -> 0 | M16: =J6*M6+J7*M7+J8*M8+J9*M9+J10*M10+J11*M11+J12*M12+J13*M13+J14*M14+J15*M15 -> 0

Sheet 2022
B2: 대출금 | I2: 예수금 | J2: 총매도금액 | K2: 총매수금액 | L2: 총평가금액 | M2: 작년대비
I3: =L3-M16 -> 0 | J3: =K16 -> 0 | K3: =L16 -> 0 | L3: ='2021'!L3+'2022'!E16+B3 -> 0 | M3: =(L3-'2015'!C3)/'2022'!L3 -> #DIV/0!
B5: 종목명 | C5: 주가 | D5: 주식수 | E5: 평가금액 | F5: 현재주가 | G5: 수익률 | I5: 종목명 | J5: 주가 | K5: 매도 | L5: 매수 | M5: 주식수
B6: A 엔터 | C6: ='2021'!J6 -> 85000 | D6: ='2021'!M6 -> 0 | E6: =(F6*D6)-(C6*D6) -> 0 | F6: =종목!C10 -> 90000 | G6: =(F6-C6)/C6 -> 0.058823529 | I6: A 엔터 | J6: =F6 -> 90000 | M6: =(D6-K6)+L6 -> 0
B7: B 여행 | C7: ='2021'!J7 -> 94300 | D7: ='2021'!M7 -> 0 | E7: =(F7*D7)-(C7*D7) -> 0 | F7: =종목!H10 -> 47150 | G7: =(F7-C7)/C7 -> -0.5 | I7: B 여행 | J7: =F7 -> 47150 | M7: =(D7-K7)+L7 -> 0
B8: C IT | C8: ='2021'!J8 -> 115000 | D8: ='2021'!M8 -> 0 | E8: =(F8*D8)-(C8*D8) -> 0 | F8: =종목!M10 -> 77200 | G8: =(F8-C8)/C8 -> -0.32869565 | I8: C IT | J8: =F8 -> 77200 | M8: =(D8-K8)+L8 -> 0
B9: D 바이오 | C9: ='2021'!J9 -> 185000 | D9: ='2021'!M9 -> 0 | E9: =(F9*D9)-(C9*D9) -> 0 | F9: =종목!C23 -> 131000 | G9: =(F9-C9)/C9 -> -0.29189189 | I9: D 바이오 | J9: =F9 -> 131000 | M9: =(D9-K9)+L9 -> 0
B10: E 자동차 | C10: ='2021'!J10 -> 289000 | D10: ='2021'!M10 -> 0 | E10: =(F10*D10)-(C10*D10) -> 0 | F10: =종목!H23 -> 160000 | G10: =(F10-C10)/C10 -> -0.44636678 | I10: E 자동차 | J10: =F10 -> 160000 | M10: =(D10-K10)+L10 -> 0
B11: F 통신 | C11: ='2021'!J11 -> 47000 | D11: ='2021'!M11 -> 0 | E11: =(F11*D11)-(C11*D11) -> 0 | F11: =종목!M23 -> 61900 | G11: =(F11-C11)/C11 -> 0.31702128 | I11: F 통신 | J11: =F11 -> 61900 | M11: =(D11-K11)+L11 -> 0
B12: G 조선 | C12: ='2021'!J12 -> 163500 | D12: ='2021'!M12 -> 0 | E12: =(F12*D12)-(C12*D12) -> 0 | F12: =종목!C36 -> 68600 | G12: =(F12-C12)/C12 -> -0.58042813 | I12: G 조선 | J12: =F12 -> 68600 | M12: =(D12-K12)+L12 -> 0
B13: H 뷰티 | C13: ='2021'!J13 -> 971000 | D13: ='2021'!M13 -> 0 | E13: =(F13*D13)-(C13*D13) -> 0 | F13: =종목!H36 -> 499500 | G13: =(F13-C13)/C13 -> -0.48558187 | I13: H 뷰티 | J13: =F13 -> 499500 | M13: =(D13-K13)+L13 -> 0
B14: I 화학 | C14: ='2021'!J14 -> 538000 | D14: ='2021'!M14 -> 0 | E14: =(F14*D14)-(C14*D14) -> 0 | F14: =종목!M36 -> 134303 | G14: =(F14-C14)/C14 -> -0.75036617 | I14: I 화학 | J14: =F14 -> 134303 | M14: =(D14-K14)+L14 -> 0
B15: J 식품 | C15: ='2021'!J15 -> 78000 | D15: ='2021'!M15 -> 0 | E15: =(F15*D15)-(C15*D15) -> 0 | F15: =종목!C49 -> 300000 | G15: =(F15-C15)/C15 -> 2.8461538 | I15: J 식품 | J15: =F15 -> 300000 | M15: =(D15-K15)+L15 -> 0
B16: 합계 | E16: =SUM(E6:E15) -> 0 | I16: 합계 | K16: =(J6*K6)+(J7*K7)+(J8*K8)+(J9*K9)+(J10*K10)+(J11*K11)+(J12*K12)+(J13*K13)+(J14*K14)+(J15*K15) -> 0 | L16: =(J6*L6)+(J7*L7)+(J8*L8)+(J9*L9)+(J10*L10)+(J11*L11)+(J12*L12)+(J13*L13)+(J14*L14)+(J15*L15) -> 0 | M16: =J6*M6+J7*M7+J8*M8+J9*M9+J10*M10+J11*M11+J12*M12+J13*M13+J14*M14+J15*M15 -> 0

Sheet 2023
B2: 대출금 | I2: 예수금 | J2: 총매도금액 | K2: 총매수금액 | L2: 총평가금액 | M2: 작년대비
I3: =L3-M16 -> 0 | J3: =K16 -> 0 | K3: =L16 -> 0 | L3: ='2022'!L3+'2023'!E16+B3 -> 0 | M3: =(L3-'2015'!C3)/'2023'!L3 -> #DIV/0!
B5: 종목명 | C5: 주가 | D5: 주식수 | E5: 평가금액 | F5: 현재주가 | G5: 수익률 | I5: 종목명 | J5: 주가 | K5: 매도 | L5: 매수 | M5: 주식수
B6: A 엔터 | C6: ='2022'!J6 -> 90000 | D6: ='2022'!M6 -> 0 | E6: =(F6*D6)-(C6*D6) -> 0 | F6: =종목!C11 -> 161200 | G6: =(F6-C6)/C6 -> 0.79111111 | I6: A 엔터 | J6: =F6 -> 161200 | M6: =(D6-K6)+L6 -> 0
B7: B 여행 | C7: ='2022'!J7 -> 47150 | D7: ='2022'!M7 -> 0 | E7: =(F7*D7)-(C7*D7) -> 0 | F7: =종목!H11 -> 53000 | G7: =(F7-C7)/C7 -> 0.12407211 | I7: B 여행 | J7: =F7 -> 53000 | M7: =(D7-K7)+L7 -> 0
B8: C IT | C8: ='2022'!J8 -> 77200 | D8: ='2022'!M8 -> 0 | E8: =(F8*D8)-(C8*D8) -> 0 | F8: =종목!M11 -> 132400 | G8: =(F8-C8)/C8 -> 0.71502591 | I8: C IT | J8: =F8 -> 132400 | M8: =(D8-K8)+L8 -> 0
B9: D 바이오 | C9: ='2022'!J9 -> 131000 | D9: ='2022'!M9 -> 0 | E9: =(F9*D9)-(C9*D9) -> 0 | F9: =종목!C24 -> 203000 | G9: =(F9-C9)/C9 -> 0.54961832 | I9: D 바이오 | J9: =F9 -> 203000 | M9: =(D9-K9)+L9 -> 0
B10: E 자동차 | C10: ='2022'!J10 -> 160000 | D10: ='2022'!M10 -> 0 | E10: =(F10*D10)-(C10*D10) -> 0 | F10: =종목!H24 -> 211500 | G10: =(F10-C10)/C10 -> 0.321875 | I10: E 자동차 | J10: =F10 -> 211500 | M10: =(D10-K10)+L10 -> 0
B11: F 통신 | C11: ='2022'!J11 -> 61900 | D11: ='2022'!M11 -> 0 | E11: =(F11*D11)-(C11*D11) -> 0 | F11: =종목!M24 -> 43300 | G11: =(F11-C11)/C11 -> -0.30048465 | I11: F 통신 | J11: =F11 -> 43300 | M11: =(D11-K11)+L11 -> 0
B12: G 조선 | C12: ='2022'!J12 -> 68600 | D12: ='2022'!M12 -> 0 | E12: =(F12*D12)-(C12*D12) -> 0 | F12: =종목!C37 -> 130000 | G12: =(F12-C12)/C12 -> 0.89504373 | I12: G 조선 | J12: =F12 -> 130000 | M12: =(D12-K12)+L12 -> 0
B13: H 뷰티 | C13: ='2022'!J13 -> 499500 | D13: ='2022'!M13 -> 0 | E13: =(F13*D13)-(C13*D13) -> 0 | F13: =종목!H37 -> 590000 | G13: =(F13-C13)/C13 -> 0.18118118 | I13: H 뷰티 | J13: =F13 -> 590000 | M13: =(D13-K13)+L13 -> 0
B14: I 화학 | C14: ='2022'!J14 -> 134303 | D14: ='2022'!M14 -> 0 | E14: =(F14*D14)-(C14*D14) -> 0 | F14: =종목!M37 -> 189700 | G14: =(F14-C14)/C14 -> 0.41247776 | I14: I 화학 | J14: =F14 -> 189700 | M14: =(D14-K14)+L14 -> 0
B15: J 식품 | C15: ='2022'!J15 -> 300000 | D15: ='2022'!M15 -> 0 | E15: =(F15*D15)-(C15*D15) -> 0 | F15: =종목!C50 -> 81500 | G15: =(F15-C15)/C15 -> -0.72833333 | I15: J 식품 | J15: =F15 -> 81500 | M15: =(D15-K15)+L15 -> 0
B16: 합계 | E16: =SUM(E6:E15) -> 0 | I16: 합계 | K16: =(J6*K6)+(J7*K7)+(J8*K8)+(J9*K9)+(J10*K10)+(J11*K11)+(J12*K12)+(J13*K13)+(J14*K14)+(J15*K15) -> 0 | L16: =(J6*L6)+(J7*L7)+(J8*L8)+(J9*L9)+(J10*L10)+(J11*L11)+(J12*L12)+(J13*L13)+(J14*L14)+(J15*L15) -> 0 | M16: =J6*M6+J7*M7+J8*M8+J9*M9+J10*M10+J11*M11+J12*M12+J13*M13+J14*M14+J15*M15 -> 0

Sheet 2024
B2: 대출금 | I2: 예수금 | J2: 총매도금액 | K2: 총매수금액 | L2: 총평가금액 | M2: 작년대비
I3: =L3-M16 -> 0 | J3: =K16 -> 0 | K3: =L16 -> 0 | L3: ='2023'!L3+'2024'!E16+B3 -> 0 | M3: =(L3-'2015'!C3)/'2024'!L3 -> #DIV/0!
B5: 종목명 | C5: 주가 | D5: 주식수 | E5: 평가금액 | F5: 현재주가 | G5: 수익률 | I5: 종목명 | J5: 주가 | K5: 매도 | L5: 매수 | M5: 주식수
B6: A 엔터 | C6: ='2023'!J6 -> 161200 | D6: ='2023'!M6 -> 0 | E6: =(F6*D6)-(C6*D6) -> 0 | F6: =종목!C12 -> 55100 | G6: =(F6-C6)/C6 -> -0.65818859 | I6: A 엔터 | J6: =F6 -> 55100 | M6: =(D6-K6)+L6 -> 0
B7: B 여행 | C7: ='2023'!J7 -> 53000 | D7: ='2023'!M7 -> 0 | E7: =(F7*D7)-(C7*D7) -> 0 | F7: =종목!H12 -> 270600 | G7: =(F7-C7)/C7 -> 4.1056604 | I7: B 여행 | J7: =F7 -> 270600 | M7: =(D7-K7)+L7 -> 0
B8: C IT | C8: ='2023'!J8 -> 132400 | D8: ='2023'!M8 -> 0 | E8: =(F8*D8)-(C8*D8) -> 0 | F8: =종목!M12 -> 86500 | G8: =(F8-C8)/C8 -> -0.34667674 | I8: C IT | J8: =F8 -> 86500 | M8: =(D8-K8)+L8 -> 0
B9: D 바이오 | C9: ='2023'!J9 -> 203000 | D9: ='2023'!M9 -> 0 | E9: =(F9*D9)-(C9*D9) -> 0 | F9: =종목!C25 -> 215000 | G9: =(F9-C9)/C9 -> 0.0591133 | I9: D 바이오 | J9: =F9 -> 215000 | M9: =(D9-K9)+L9 -> 0
B10: E 자동차 | C10: ='2023'!J10 -> 211500 | D10: ='2023'!M10 -> 0 | E10: =(F10*D10)-(C10*D10) -> 0 | F10: =종목!H25 -> 299500 | G10: =(F10-C10)/C10 -> 0.41607565 | I10: E 자동차 | J10: =F10 -> 299500 | M10: =(D10-K10)+L10 -> 0
B11: F 통신 | C11: ='2023'!J11 -> 43300 | D11: ='2023'!M11 -> 0 | E11: =(F11*D11)-(C11*D11) -> 0 | F11: =종목!M25 -> 61900 | G11: =(F11-C11)/C11 -> 0.4295612 | I11: F 통신 | J11: =F11 -> 61900 | M11: =(D11-K11)+L11 -> 0
B12: G 조선 | C12: ='2023'!J12 -> 130000 | D12: ='2023'!M12 -> 0 | E12: =(F12*D12)-(C12*D12) -> 0 | F12: =종목!C38 -> 219000 | G12: =(F12-C12)/C12 -> 0.68461538 | I12: G 조선 | J12: =F12 -> 219000 | M12: =(D12-K12)+L12 -> 0
B13: H 뷰티 | C13: ='2023'!J13 -> 590000 | D13: ='2023'!M13 -> 0 | E13: =(F13*D13)-(C13*D13) -> 0 | F13: =종목!H38 -> 300000 | G13: =(F13-C13)/C13 -> -0.49152542 | I13: H 뷰티 | J13: =F13 -> 300000 | M13: =(D13-K13)+L13 -> 0
B14: I 화학 | C14: ='2023'!J14 -> 189700 | D14: ='2023'!M14 -> 0 | E14: =(F14*D14)-(C14*D14) -> 0 | F14: =종목!M38 -> 62200 | G14: =(F14-C14)/C14 -> -0.67211386 | I14: I 화학 | J14: =F14 -> 62200 | M14: =(D14-K14)+L14 -> 0
B15: J 식품 | C15: ='2023'!J15 -> 81500 | D15: ='2023'!M15 -> 0 | E15: =(F15*D15)-(C15*D15) -> 0 | F15: =종목!C51 -> 126400 | G15: =(F15-C15)/C15 -> 0.55092025 | I15: J 식품 | J15: =F15 -> 126400 | M15: =(D15-K15)+L15 -> 0
B16: 합계 | E16: =SUM(E6:E15) -> 0 | I16: 합계 | K16: =(J6*K6)+(J7*K7)+(J8*K8)+(J9*K9)+(J10*K10)+(J11*K11)+(J12*K12)+(J13*K13)+(J14*K14)+(J15*K15) -> 0 | L16: =(J6*L6)+(J7*L7)+(J8*L8)+(J9*L9)+(J10*L10)+(J11*L11)+(J12*L12)+(J13*L13)+(J14*L14)+(J15*L15) -> 0 | M16: =J6*M6+J7*M7+J8*M8+J9*M9+J10*M10+J11*M11+J12*M12+J13*M13+J14*M14+J15*M15 -> 0

Sheet 2025
B2: 대출금총액 | C2: 대출금이자 | D2: 최종금액 | I2: 예수금 | J2: 총매도금액 | K2: 총매수금액 | L2: 총평가금액 | M2: 작년대비
B3: ='2015'!E3+'2016'!B3+'2017'!B3+'2018'!B3+'2019'!B3+'2020'!B3+'2021'!B3+'2022'!B3+'2023'!B3+'2024'!B3 -> 0 | C3: =B3 -> 0 | D3: =L3-(B3+C3) -> 0 | I3: =L3-M16 -> 0 | J3: =K16 -> 0 | K3: =L16 -> 0 | L3: ='2024'!L3+'2025'!E16+B3 -> 0 | M3: =(L3-'2015'!C3)/'2025'!L3 -> #DIV/0!
B5: 종목명 | C5: 주가 | D5: 주식수 | E5: 평가금액 | F5: 현재주가 | G5: 수익률 | I5: 종목명 | J5: 주가 | K5: 매도 | L5: 매수 | M5: 주식수
B6: A 엔터 | C6: ='2024'!J6 -> 55100 | D6: ='2024'!M6 -> 0 | E6: =(F6*D6)-(C6*D6) -> 0 | F6: =종목!C13 -> 82700 | G6: =(F6-C6)/C6 -> 0.50090744 | I6: A 엔터 | J6: =F6 -> 82700 | M6: =(D6-K6)+L6 -> 0
B7: B 여행 | C7: ='2024'!J7 -> 270600 | D7: ='2024'!M7 -> 0 | E7: =(F7*D7)-(C7*D7) -> 0 | F7: =종목!H13 -> 58600 | G7: =(F7-C7)/C7 -> -0.7834442 | I7: B 여행 | J7: =F7 -> 58600 | M7: =(D7-K7)+L7 -> 0
B8: C IT | C8: ='2024'!J8 -> 86500 | D8: ='2024'!M8 -> 0 | E8: =(F8*D8)-(C8*D8) -> 0 | F8: =종목!M13 -> 86500 | G8: =(F8-C8)/C8 -> 0 | I8: C IT | J8: =F8 -> 86500 | M8: =(D8-K8)+L8 -> 0
B9: D 바이오 | C9: ='2024'!J9 -> 215000 | D9: ='2024'!M9 -> 0 | E9: =(F9*D9)-(C9*D9) -> 0 | F9: =종목!C26 -> 144000 | G9: =(F9-C9)/C9 -> -0.33023256 | I9: D 바이오 | J9: =F9 -> 144000 | M9: =(D9-K9)+L9 -> 0
B10: E 자동차 | C10: ='2024'!J10 -> 299500 | D10: ='2024'!M10 -> 0 | E10: =(F10*D10)-(C10*D10) -> 0 | F10: =종목!H26 -> 990000 | G10: =(F10-C10)/C10 -> 2.3055092 | I10: E 자동차 | J10: =F10 -> 990000 | M10: =(D10-K10)+L10 -> 0
B11: F 통신 | C11: ='2024'!J11 -> 61900 | D11: ='2024'!M11 -> 0 | E11: =(F11*D11)-(C11*D11) -> 0 | F11: =종목!M26 -> 75100 | G11: =(F11-C11)/C11 -> 0.21324717 | I11: F 통신 | J11: =F11 -> 75100 | M11: =(D11-K11)+L11 -> 0
B12: G 조선 | C12: ='2024'!J12 -> 219000 | D12: ='2024'!M12 -> 0 | E12: =(F12*D12)-(C12*D12) -> 0 | F12: =종목!C39 -> 994500 | G12: =(F12-C12)/C12 -> 3.5410959 | I12: G 조선 | J12: =F12 -> 994500 | M12: =(D12-K12)+L12 -> 0
B13: H 뷰티 | C13: ='2024'!J13 -> 300000 | D13: ='2024'!M13 -> 0 | E13: =(F13*D13)-(C13*D13) -> 0 | F13: =종목!H39 -> 300000 | G13: =(F13-C13)/C13 -> 0 | I13: H 뷰티 | J13: =F13 -> 300000 | M13: =(D13-K13)+L13 -> 0
B14: I 화학 | C14: ='2024'!J14 -> 62200 | D14: ='2024'!M14 -> 0 | E14: =(F14*D14)-(C14*D14) -> 0 | F14: =종목!M39 -> 51800 | G14: =(F14-C14)/C14 -> -0.16720257 | I14: I 화학 | J14: =F14 -> 51800 | M14: =(D14-K14)+L14 -> 0
B15: J 식품 | C15: ='2024'!J15 -> 126400 | D15: ='2024'!M15 -> 0 | E15: =(F15*D15)-(C15*D15) -> 0 | F15: =종목!C52 -> 557800 | G15: =(F15-C15)/C15 -> 3.4129747 | I15: J 식품 | J15: =F15 -> 557800 | M15: =(D15-K15)+L15 -> 0
B16: 합계 | E16: =SUM(E6:E15) -> 0 | I16: 합계 | K16: =(J6*K6)+(J7*K7)+(J8*K8)+(J9*K9)+(J10*K10)+(J11*K11)+(J12*K12)+(J13*K13)+(J14*K14)+(J15*K15) -> 0 | L16: =(J6*L6)+(J7*L7)+(J8*L8)+(J9*L9)+(J10*L10)+(J11*L11)+(J12*L12)+(J13*L13)+(J14*L14)+(J15*L15) -> 0 | M16: =J6*M6+J7*M7+J8*M8+J9*M9+J10*M10+J11*M11+J12*M12+J13*M13+J14*M14+J15*M15 -> 0

Sheet 종목
B2: A 엔터 | C2: 주가 | D2: 에스엠 | E2: 등락률 | G2: B 여행 | H2: 주가 | I2: 하나투어 | J2: 등락률 | L2: C IT | M2: 주가 | N2: LG전자 | O2: 등락률 | R2: 종목 | S2: 2014 | T2: 2015 | U2: 2016 | V2: 2017 | W2: 2018 | X2: 2019 | Y2: 2020 | Z2: 2021 | AA2: 2022 | AB2: 2023 | AC2: 2024
B3: =[1]종목!B3 -> 2015 | C3: =[1]종목!$C$3 -> 49700 | D3: =[1]종목!D3 -> 11월 | G3: =[1]종목!G3 -> 2015 | H3: =[1]종목!$H3 -> 60500 | I3: =[1]종목!I3 -> 7월 | L3: =[1]종목!L3 -> 2015 | M3: =[1]종목!$M3 -> 39300 | N3: =[1]종목!N3 -> 8월 | Q3: =B2 -> A 엔터 | R3: =D2 -> 에스엠 | S3: {=INDEX($C:$C,COLUMN(S3)-COLUMN($S$3)+3)} -> 49700 | T3: {=INDEX($C:$C,COLUMN(T3)-COLUMN($S$3)+3)} -> 23800 | U3: {=INDEX($C:$C,COLUMN(U3)-COLUMN($S$3)+3)} -> 39150 | V3: {=INDEX($C:$C,COLUMN(V3)-COLUMN($S$3)+3)} -> 156900 | W3: {=INDEX($C:$C,COLUMN(W3)-COLUMN($S$3)+3)} -> 27000 | X3: {=INDEX($C:$C,COLUMN(X3)-COLUMN($S$3)+3)} -> 16350 | Y3: {=INDEX($C:$C,COLUMN(Y3)-COLUMN($S$3)+3)} -> 85000 | Z3: {=INDEX($C:$C,COLUMN(Z3)-COLUMN($S$3)+3)} -> 90000 | ... AC3: {=INDEX($C:$C,COLUMN(AC3)-COLUMN($S$3)+3)} -> 82700
B4: =[1]종목!B4 -> 2016 | C4: =[1]종목!$C$4 -> 23800 | D4: =[1]종목!D4 -> 11월 | E4: =(C4-C3)/C3 -> -0.52112676 | G4: =[1]종목!G4 -> 2016 | H4: =[1]종목!$H4 -> 205000 | I4: =[1]종목!I4 -> 10월 | J4: =(H4-H3)/H3 -> 2.3884298 | L4: =[1]종목!L4 -> 2016 | M4: =[1]종목!$M4 -> 44700 | N4: =[1]종목!N4 -> 12월 | O4: =(M4-M3)/M3 -> 0.13740458 | Q4: =G2 -> B 여행 | R4: =I2 -> 하나투어 | S4: {=INDEX($H:$H,COLUMN(S3)-COLUMN($S$3)+3)} -> 60500 | T4: {=INDEX($H:$H,COLUMN(T3)-COLUMN($S$3)+3)} -> 205000 | U4: {=INDEX($H:$H,COLUMN(U3)-COLUMN($S$3)+3)} -> 62500 | V4: {=INDEX($H:$H,COLUMN(V3)-COLUMN($S$3)+3)} -> 55900 | W4: {=INDEX($H:$H,COLUMN(W3)-COLUMN($S$3)+3)} -> 76400 | X4: {=INDEX($H:$H,COLUMN(X3)-COLUMN($S$3)+3)} -> 26600 | Y4: {=INDEX($H:$H,COLUMN(Y3)-COLUMN($S$3)+3)} -> 94300 | Z4: {=INDEX($H:$H,COLUMN(Z3)-COLUMN($S$3)+3)} -> 47150 | ... AC4: {=INDEX($H:$H,COLUMN(AC3)-COLUMN($S$3)+3)} -> 58600
B5: =[1]종목!B5 -> 2017 | C5: =[1]종목!$C$5 -> 39150 | D5: =[1]종목!D5 -> 12월 | E5: =(C5-C4)/C4 -> 0.64495798 | G5: =[1]종목!G5 -> 2017 | H5: =[1]종목!$H5 -> 62500 | I5: =[1]종목!I5 -> 1월 | J5: =(H5-H4)/H4 -> -0.69512195 | L5: =[1]종목!L5 -> 2017 | M5: =[1]종목!$M5 -> 109500 | N5: =[1]종목!N5 -> 12월 | O5: =(M5-M4)/M4 -> 1.4496644 | Q5: =L2 -> C IT | R5: =N2 -> LG전자 | S5: {=INDEX($M:$M,COLUMN(S3)-COLUMN($S$3)+3)} -> 39300 | T5: {=INDEX($M:$M,COLUMN(T3)-COLUMN($S$3)+3)} -> 44700 | U5: {=INDEX($M:$M,COLUMN(U3)-COLUMN($S$3)+3)} -> 109500 | V5: {=INDEX($M:$M,COLUMN(V3)-COLUMN($S$3)+3)} -> 58800 | W5: {=INDEX($M:$M,COLUMN(W3)-COLUMN($S$3)+3)} -> 58500 | X5: {=INDEX($M:$M,COLUMN(X3)-COLUMN($S$3)+3)} -> 236500 | Y5: {=INDEX($M:$M,COLUMN(Y3)-COLUMN($S$3)+3)} -> 115000 | Z5: {=INDEX($M:$M,COLUMN(Z3)-COLUMN($S$3)+3)} -> 77200 | ... AC5: {=INDEX($M:$M,COLUMN(AC3)-COLUMN($S$3)+3)} -> 86500
B6: =[1]종목!B6 -> 2018 | C6: =[1]종목!$C$6 -> 156900 | D6: =[1]종목!D6 -> 11월 | E6: =(C6-C5)/C5 -> 3.0076628 | G6: =[1]종목!G6 -> 2018 | H6: =[1]종목!$H6 -> 55900 | I6: =[1]종목!I6 -> 10월 | J6: =(H6-H5)/H5 -> -0.1056 | L6: =[1]종목!L6 -> 2018 | M6: =[1]종목!$M6 -> 58800 | N6: =[1]종목!N6 -> 10월 | O6: =(M6-M5)/M5 -> -0.4630137 | Q6: =B15 -> D 바이오 | R6: =D15 -> LG화학 | S6: {=INDEX($C:$C,COLUMN(S6)-COLUMN($S$6)+16)} -> 35000 | T6: {=INDEX($C:$C,COLUMN(T6)-COLUMN($S$6)+16)} -> 108000 | U6: {=INDEX($C:$C,COLUMN(U6)-COLUMN($S$6)+16)} -> 196000 | V6: {=INDEX($C:$C,COLUMN(V6)-COLUMN($S$6)+16)} -> 374000 | W6: {=INDEX($C:$C,COLUMN(W6)-COLUMN($S$6)+16)} -> 125000 | X6: {=INDEX($C:$C,COLUMN(X6)-COLUMN($S$6)+16)} -> 565000 | Y6: {=INDEX($C:$C,COLUMN(Y6)-COLUMN($S$6)+16)} -> 185000 | Z6: {=INDEX($C:$C,COLUMN(Z6)-COLUMN($S$6)+16)} -> 131000 | ... AC6: {=INDEX($C:$C,COLUMN(AC6)-COLUMN($S$6)+16)} -> 144000
B7: =[1]종목!B7 -> 2019 | C7: =[1]종목!$C$7 -> 27000 | D7: =[1]종목!D7 -> 8월 | E7: =(C7-C6)/C6 -> -0.82791587 | G7: =[1]종목!G7 -> 2019 | H7: =[1]종목!$H7 -> 76400 | I7: =[1]종목!I7 -> 12월 | J7: =(H7-H6)/H6 -> 0.3667263 | L7: =[1]종목!L7 -> 2019 | M7: =[1]종목!$M7 -> 58500 | N7: =[1]종목!N7 -> 8월 | O7: =(M7-M6)/M6 -> -0.0051020408 | Q7: =G15 -> E 자동차 | R7: =I15 -> 현대차 | S7: {=INDEX($H:$H,COLUMN(S6)-COLUMN($S$6)+16)} -> 123000 | T7: {=INDEX($H:$H,COLUMN(T6)-COLUMN($S$6)+16)} -> 126500 | U7: {=INDEX($H:$H,COLUMN(U6)-COLUMN($S$6)+16)} -> 133000 | V7: {=INDEX($H:$H,COLUMN(V6)-COLUMN($S$6)+16)} -> 92500 | W7: {=INDEX($H:$H,COLUMN(W6)-COLUMN($S$6)+16)} -> 143500 | X7: {=INDEX($H:$H,COLUMN(X6)-COLUMN($S$6)+16)} -> 199000 | Y7: {=INDEX($H:$H,COLUMN(Y6)-COLUMN($S$6)+16)} -> 289000 | Z7: {=INDEX($H:$H,COLUMN(Z6)-COLUMN($S$6)+16)} -> 160000 | ... AC7: {=INDEX($H:$H,COLUMN(AC6)-COLUMN($S$6)+16)} -> 990000
B8: =[1]종목!B8 -> 2020 | C8: =[1]종목!$C$8 -> 16350 | D8: =[1]종목!D8 -> 3월 | E8: =(C8-C7)/C7 -> -0.39444444 | G8: =[1]종목!G8 -> 2020 | H8: =[1]종목!$H8 -> 26600 | I8: =[1]종목!I8 -> 3월 | J8: =(H8-H7)/H7 -> -0.65183246 | L8: =[1]종목!L8 -> 2020 | M8: =[1]종목!$M8 -> 236500 | N8: =[1]종목!N8 -> 12월 | O8: =(M8-M7)/M7 -> 3.042735 | Q8: =L15 -> F 통신 | R8: =N15 -> SK텔레콤 | S8: {=INDEX($M:$M,COLUMN(S6)-COLUMN($S$6)+16)} -> 42800 | T8: {=INDEX($M:$M,COLUMN(T6)-COLUMN($S$6)+16)} -> 38300 | U8: {=INDEX($M:$M,COLUMN(U6)-COLUMN($S$6)+16)} -> 57600 | V8: {=INDEX($M:$M,COLUMN(V6)-COLUMN($S$6)+16)} -> 58200 | W8: {=INDEX($M:$M,COLUMN(W6)-COLUMN($S$6)+16)} -> 458000 | X8: {=INDEX($M:$M,COLUMN(X6)-COLUMN($S$6)+16)} -> 50300 | Y8: {=INDEX($M:$M,COLUMN(Y6)-COLUMN($S$6)+16)} -> 47000 | Z8: {=INDEX($M:$M,COLUMN(Z6)-COLUMN($S$6)+16)} -> 61900 | ... AC8: {=INDEX($M:$M,COLUMN(AC6)-COLUMN($S$6)+16)} -> 75100
B9: =[1]종목!B9 -> 2021 | C9: =[1]종목!$C$9 -> 85000 | D9: =[1]종목!D9 -> 10월 | E9: =(C9-C8)/C8 -> 4.1987768 | G9: =[1]종목!G9 -> 2021 | H9: =[1]종목!$H9 -> 94300 | I9: =[1]종목!I9 -> 6월 | J9: =(H9-H8)/H8 -> 2.5451128 | L9: =[1]종목!L9 -> 2021 | M9: =[1]종목!$M9 -> 115000 | N9: =[1]종목!N9 -> 11월 | O9: =(M9-M8)/M8 -> -0.51374207 | Q9: =B28 -> G 조선 | R9: =D28 -> 한국조선해양 | S9: {=INDEX($C:$C,COLUMN(S6)-COLUMN($S$6)+29)} -> 80600 | T9: {=INDEX($C:$C,COLUMN(T6)-COLUMN($S$6)+29)} -> 166000 | U9: {=INDEX($C:$C,COLUMN(U6)-COLUMN($S$6)+29)} -> 187500 | V9: {=INDEX($C:$C,COLUMN(V6)-COLUMN($S$6)+29)} -> 93700 | W9: {=INDEX($C:$C,COLUMN(W6)-COLUMN($S$6)+29)} -> 93800 | X9: {=INDEX($C:$C,COLUMN(X6)-COLUMN($S$6)+29)} -> 64200 | Y9: {=INDEX($C:$C,COLUMN(Y6)-COLUMN($S$6)+29)} -> 163500 | Z9: {=INDEX($C:$C,COLUMN(Z6)-COLUMN($S$6)+29)} -> 68600 | ... AC9: {=INDEX($C:$C,COLUMN(AC6)-COLUMN($S$6)+29)} -> 994500
B10: =[1]종목!B10 -> 2022 | C10: =[1]종목!$C$10 -> 90000 | D10: =[1]종목!D10 -> 4월 | E10: =(C10-C9)/C9 -> 0.058823529 | G10: =[1]종목!G10 -> 2022 | H10: =[1]종목!$H10 -> 47150 | I10: =[1]종목!I10 -> 11월 | J10: =(H10-H9)/H9 -> -0.5 | L10: =[1]종목!L10 -> 2022 | M10: =[1]종목!$M10 -> 77200 | N10: =[1]종목!N10 -> 10월 | O10: =(M10-M9)/M9 -> -0.32869565 | Q10: =G28 -> H 뷰티 | R10: =I28 -> LG생활건강 | S10: {=INDEX($H:$H,COLUMN(S6)-COLUMN($S$6)+29)} -> 1066000 | T10: {=INDEX($H:$H,COLUMN(T6)-COLUMN($S$6)+29)} -> 740000 | U10: {=INDEX($H:$H,COLUMN(U6)-COLUMN($S$6)+29)} -> 774000 | V10: {=INDEX($H:$H,COLUMN(V6)-COLUMN($S$6)+29)} -> 1010000 | W10: {=INDEX($H:$H,COLUMN(W6)-COLUMN($S$6)+29)} -> 1466000 | X10: {=INDEX($H:$H,COLUMN(X6)-COLUMN($S$6)+29)} -> 3649000 | Y10: {=INDEX($H:$H,COLUMN(Y6)-COLUMN($S$6)+29)} -> 971000 | Z10: {=INDEX($H:$H,COLUMN(Z6)-COLUMN($S$6)+29)} -> 499500 | ... AC10: {=INDEX($H:$H,COLUMN(AC6)-COLUMN($S$6)+29)} -> 300000
B11: =[1]종목!B11 -> 2023 | C11: =[1]종목!$C$11 -> 161200 | D11: =[1]종목!D11 -> 3월 | E11: =(C11-C10)/C10 -> 0.79111111 | G11: =[1]종목!G11 -> 2023 | H11: =[1]종목!$H11 -> 53000 | I11: =[1]종목!I11 -> 8월 | J11: =(H11-H10)/H10 -> 0.12407211 | L11: =[1]종목!L11 -> 2023 | M11: =[1]종목!$M11 -> 132400 | N11: =[1]종목!N11 -> 7월 | O11: =(M11-M10)/M10 -> 0.71502591 | Q11: =L28 -> I 화학 | R11: =N28 -> 롯데케미칼 | S11: {=INDEX($M:$M,COLUMN(S6)-COLUMN($S$6)+29)} -> 305000 | T11: {=INDEX($M:$M,COLUMN(T6)-COLUMN($S$6)+29)} -> 370000 | U11: {=INDEX($M:$M,COLUMN(U6)-COLUMN($S$6)+29)} -> 422000 | V11: {=INDEX($M:$M,COLUMN(V6)-COLUMN($S$6)+29)} -> 247000 | W11: {=INDEX($M:$M,COLUMN(W6)-COLUMN($S$6)+29)} -> 207500 | X11: {=INDEX($M:$M,COLUMN(X6)-COLUMN($S$6)+29)} -> 114500 | Y11: {=INDEX($M:$M,COLUMN(Y6)-COLUMN($S$6)+29)} -> 538000 | Z11: {=INDEX($M:$M,COLUMN(Z6)-COLUMN($S$6)+29)} -> 134303 | ... AC11: {=INDEX($M:$M,COLUMN(AC6)-COLUMN($S$6)+29)} -> 51800
B12: =[1]종목!B12 -> 2024 | C12: =[1]종목!$C$12 -> 55100 | D12: =[1]종목!D12 -> 9월 | E12: =(C12-C11)/C11 -> -0.65818859 | G12: =[1]종목!G12 -> 2024 | H12: =[1]종목!$H12 -> 270600 | I12: =[1]종목!I12 -> 4월 | J12: =(H12-H11)/H11 -> 4.1056604 | L12: =[1]종목!L12 -> 2024 | M12: =[1]종목!$M12 -> 86500 | N12: =[1]종목!N12 -> 8월 | O12: =(M12-M11)/M11 -> -0.34667674 | Q12: =B41 -> J 식품 | R12: =D41 -> KT&G | S12: {=INDEX($C:$C,COLUMN(S6)-COLUMN($S$6)+42)} -> 120500 | T12: {=INDEX($C:$C,COLUMN(T6)-COLUMN($S$6)+42)} -> 139500 | U12: {=INDEX($C:$C,COLUMN(U6)-COLUMN($S$6)+42)} -> 94900 | V12: {=INDEX($C:$C,COLUMN(V6)-COLUMN($S$6)+42)} -> 95500 | W12: {=INDEX($C:$C,COLUMN(W6)-COLUMN($S$6)+42)} -> 93700 | X12: {=INDEX($C:$C,COLUMN(X6)-COLUMN($S$6)+42)} -> 98100 | Y12: {=INDEX($C:$C,COLUMN(Y6)-COLUMN($S$6)+42)} -> 78000 | Z12: {=INDEX($C:$C,COLUMN(Z6)-COLUMN($S$6)+42)} -> 300000 | ... AC12: {=INDEX($C:$C,COLUMN(AC6)-COLUMN($S$6)+42)} -> 557800
B13: =[1]종목!B13 -> 2025 | C13: =[1]종목!$C$13 -> 82700 | D13: =[1]종목!D13 -> 2월 | E13: =(C13-C12)/C12 -> 0.50090744 | G13: =[1]종목!G13 -> 2025 | H13: =[1]종목!$H13 -> 58600 | I13: =[1]종목!I13 -> 2월 | J13: =(H13-H12)/H12 -> -0.7834442 | L13: =[1]종목!L13 -> 2025 | M13: 86500 | N13: =[1]종목!N13 -> 4월 | O13: =(M13-M12)/M12 -> 0
B15: D 바이오 | C15: 주가 | D15: LG화학 | E15: 등락률 | G15: E 자동차 | H15: 주가 | I15: 현대차 | J15: 등락률 | L15: F 통신 | M15: 주가 | N15: SK텔레콤 | O15: 등락률
B16: =[1]종목!B16 -> 2015 | C16: =[1]종목!$C16 -> 35000 | D16: =[1]종목!D16 -> 12월 | G16: =[1]종목!G16 -> 2015 | H16: =[1]종목!$H16 -> 123000 | I16: =[1]종목!I16 -> 7월 | L16: =[1]종목!L16 -> 2015 | M16: =[1]종목!$M16 -> 42800 | N16: =[1]종목!N16 -> 12월
B17: =[1]종목!B17 -> 2016 | C17: =[1]종목!$C17 -> 108000 | D17: =[1]종목!D17 -> 11월 | E17: =(C17-C16)/C16 -> 2.0857143 | G17: =[1]종목!G17 -> 2016 | H17: =[1]종목!$H17 -> 126500 | I17: =[1]종목!I17 -> 2월 | J17: =(H17-H16)/H16 -> 0.028455285 | L17: =[1]종목!L17 -> 2016 | M17: =[1]종목!$M17 -> 38300 | N17: =[1]종목!N17 -> 1월 | O17: =(M17-M16)/M16 -> -0.10514019
B18: =[1]종목!B18 -> 2017 | C18: =[1]종목!$C18 -> 196000 | D18: =[1]종목!D18 -> 11월 | E18: =(C18-C17)/C17 -> 0.81481481 | G18: =[1]종목!G18 -> 2017 | H18: =[1]종목!$H18 -> 133000 | I18: =[1]종목!I18 -> 9월 | J18: =(H18-H17)/H17 -> 0.051383399 | L18: =[1]종목!L18 -> 2017 | M18: =[1]종목!$M18 -> 57600 | N18: =[1]종목!N18 -> 8월 | O18: =(M18-M17)/M17 -> 0.50391645
B19: =[1]종목!B19 -> 2018 | C19: =[1]종목!$C19 -> 374000 | D19: =[1]종목!D19 -> 10월 | E19: =(C19-C18)/C18 -> 0.90816327 | G19: =[1]종목!G19 -> 2018 | H19: =[1]종목!$H19 -> 92500 | I19: =[1]종목!I19 -> 11월 | J19: =(H19-H18)/H18 -> -0.30451128 | L19: =[1]종목!L19 -> 2018 | M19: =[1]종목!$M19 -> 58200 | N19: =[1]종목!N19 -> 11월 | O19: =(M19-M18)/M18 -> 0.010416667
B20: =[1]종목!B20 -> 2019 | C20: =[1]종목!$C20 -> 125000 | D20: =[1]종목!D20 -> 10월 | E20: =(C20-C19)/C19 -> -0.6657754 | G20: =[1]종목!G20 -> 2019 | H20: =[1]종목!$H20 -> 143500 | I20: =[1]종목!I20 -> 6월 | J20: =(H20-H19)/H19 -> 0.55135135 | L20: =[1]종목!L20 -> 2019 | M20: =[1]종목!$M20 -> 458000 | N20: =[1]종목!N20 -> 8월 | O20: =(M20-M19)/M19 -> 6.8694158
B21: =[1]종목!B21 -> 2020 | C21: =[1]종목!$C21 -> 565000 | D21: =[1]종목!D21 -> 12월 | E21: =(C21-C20)/C20 -> 3.52 | G21: =[1]종목!G21 -> 2020 | H21: =[1]종목!$H21 -> 199000 | I21: =[1]종목!I21 -> 12월 | J21: =(H21-H20)/H20 -> 0.38675958 | L21: =[1]종목!L21 -> 2020 | M21: =[1]종목!$M21 -> 50300 | N21: =[1]종목!N21 -> 8월 | O21: =(M21-M20)/M20 -> -0.89017467
B22: =[1]종목!B22 -> 2021 | C22: =[1]종목!$C22 -> 185000 | D22: =[1]종목!D22 -> 12월 | E22: =(C22-C21)/C21 -> -0.67256637 | G22: =[1]종목!G22 -> 2021 | H22: =[1]종목!$H22 -> 289000 | I22: =[1]종목!I22 -> 1월 | J22: =(H22-H21)/H21 -> 0.45226131 | L22: =[1]종목!L22 -> 2021 | M22: =[1]종목!$M22 -> 47000 | N22: =[1]종목!N22 -> 1월 | O22: =(M22-M21)/M21 -> -0.065606362
B23: =[1]종목!B23 -> 2022 | C23: =[1]종목!$C23 -> 131000 | D23: =[1]종목!D23 -> 3월 | E23: =(C23-C22)/C22 -> -0.29189189 | G23: =[1]종목!G23 -> 2022 | H23: =[1]종목!$H23 -> 160000 | I23: =[1]종목!I23 -> 11월 | J23: =(H23-H22)/H22 -> -0.44636678 | L23: =[1]종목!L23 -> 2022 | M23: =[1]종목!$M23 -> 61900 | N23: =[1]종목!N23 -> 4월 | O23: =(M23-M22)/M22 -> 0.31702128
B24: =[1]종목!B24 -> 2023 | C24: =[1]종목!$C24 -> 203000 | D24: =[1]종목!D24 -> 4월 | E24: =(C24-C23)/C23 -> 0.54961832 | G24: =[1]종목!G24 -> 2023 | H24: =[1]종목!$H24 -> 211500 | I24: =[1]종목!I24 -> 5월 | J24: =(H24-H23)/H23 -> 0.321875 | L24: =[1]종목!L24 -> 2023 | M24: =[1]종목!$M24 -> 43300 | N24: =[1]종목!N24 -> 7월 | O24: =(M24-M23)/M23 -> -0.30048465
B25: =[1]종목!B25 -> 2024 | C25: =[1]종목!$C25 -> 215000 | D25: =[1]종목!D25 -> 12월 | E25: =(C25-C24)/C24 -> 0.0591133 | G25: =[1]종목!G25 -> 2024 | H25: =[1]종목!$H25 -> 299500 | I25: =[1]종목!I25 -> 7월 | J25: =(H25-H24)/H24 -> 0.41607565 | L25: =[1]종목!L25 -> 2024 | M25: =[1]종목!$M25 -> 61900 | N25: =[1]종목!N25 -> 12월 | O25: =(M25-M24)/M24 -> 0.4295612
B26: =[1]종목!B26 -> 2025 | C26: =[1]종목!$C26 -> 144000 | D26: =[1]종목!D26 -> 5월 | E26: =(C26-C25)/C25 -> -0.33023256 | G26: =[1]종목!G26 -> 2025 | H26: =[1]종목!$H26 -> 990000 | I26: =[1]종목!I26 -> 12월 | J26: =(H26-H25)/H25 -> 2.3055092 | L26: =[1]종목!L26 -> 2025 | M26: =[1]종목!$M26 -> 75100 | N26: =[1]종목!N26 -> 12월 | O26: =(M26-M25)/M25 -> 0.21324717
B28: G 조선 | C28: 주가 | D28: 한국조선해양 | E28: 등락률 | G28: H 뷰티 | H28: 주가 | I28: LG생활건강 | J28: 등락률 | L28: I 화학 | M28: 주가 | N28: 롯데케미칼 | O28: 등락률
B29: =[1]종목!B29 -> 2015 | C29: =[1]종목!$C29 -> 80600 | D29: =[1]종목!D29 -> 8월 | G29: =[1]종목!G29 -> 2015 | H29: =[1]종목!$H29 -> 1066000 | I29: =[1]종목!I29 -> 12월 | L29: =[1]종목!L29 -> 2015 | M29: =[1]종목!$M29 -> 305000 | N29: =[1]종목!N29 -> 6월
B30: =[1]종목!B30 -> 2016 | C30: =[1]종목!$C30 -> 166000 | D30: =[1]종목!D30 -> 11월 | E30: =(C30-C29)/C29 -> 1.0595533 | G30: =[1]종목!G30 -> 2016 | H30: =[1]종목!$H30 -> 740000 | I30: =[1]종목!I30 -> 11월 | J30: =(H30-H29)/H29 -> -0.30581614 | L30: =[1]종목!L30 -> 2016 | M30: =[1]종목!$M30 -> 370000 | N30: =[1]종목!N30 -> 12월 | O30: =(M30-M29)/M29 -> 0.21311475
B31: =[1]종목!B31 -> 2017 | C31: =[1]종목!$C31 -> 187500 | D31: =[1]종목!D31 -> 6월 | E31: =(C31-C30)/C30 -> 0.12951807 | G31: =[1]종목!G31 -> 2017 | H31: =[1]종목!$H31 -> 774000 | I31: =[1]종목!I31 -> 3월 | J31: =(H31-H30)/H30 -> 0.045945946 | L31: =[1]종목!L31 -> 2017 | M31: =[1]종목!$M31 -> 422000 | N31: =[1]종목!N31 -> 9월 | O31: =(M31-M30)/M30 -> 0.14054054
B32: =[1]종목!B32 -> 2018 | C32: =[1]종목!$C32 -> 93700 | D32: =[1]종목!D32 -> 10월 | E32: =(C32-C31)/C31 -> -0.50026667 | G32: =[1]종목!G32 -> 2018 | H32: =[1]종목!$H32 -> 1010000 | I32: =[1]종목!I32 -> 10월 | J32: =(H32-H31)/H31 -> 0.30490956 | L32: =[1]종목!L32 -> 2018 | M32: =[1]종목!$M32 -> 247000 | N32: =[1]종목!N32 -> 10월 | O32: =(M32-M31)/M31 -> -0.41469194
B33: =[1]종목!B33 -> 2019 | C33: =[1]종목!$C33 -> 93800 | D33: =[1]종목!D33 -> 8월 | E33: =(C33-C32)/C32 -> 0.0010672359 | G33: =[1]종목!G33 -> 2019 | H33: =[1]종목!$H33 -> 1466000 | I33: =[1]종목!I33 -> 4월 | J33: =(H33-H32)/H32 -> 0.45148515 | L33: =[1]종목!L33 -> 2019 | M33: =[1]종목!$M33 -> 207500 | N33: =[1]종목!N33 -> 8월 | O33: =(M33-M32)/M32 -> -0.15991903
B34: =[1]종목!B34 -> 2020 | C34: =[1]종목!$C34 -> 64200 | D34: =[1]종목!D34 -> 3월 | E34: =(C34-C33)/C33 -> -0.31556503 | G34: =[1]종목!G34 -> 2020 | H34: =[1]종목!$H34 -> 3649000 | I34: =[1]종목!I34 -> 12월 | J34: =(H34-H33)/H33 -> 1.4890859 | L34: =[1]종목!L34 -> 2020 | M34: =[1]종목!$M34 -> 114500 | N34: =[1]종목!N34 -> 3월 | O34: =(M34-M33)/M33 -> -0.44819277
B35: =[1]종목!B35 -> 2021 | C35: =[1]종목!$C35 -> 163500 | D35: =[1]종목!D35 -> 5월 | E35: =(C35-C34)/C34 -> 1.546729 | G35: =[1]종목!G35 -> 2021 | H35: =[1]종목!$H35 -> 971000 | I35: =[1]종목!I35 -> 12월 | J35: =(H35-H34)/H34 -> -0.7338997 | L35: =[1]종목!L35 -> 2021 | M35: =[1]종목!$M35 -> 538000 | N35: =[1]종목!N35 -> 3월 | O35: =(M35-M34)/M34 -> 3.69869
B36: =[1]종목!B36 -> 2022 | C36: =[1]종목!$C36 -> 68600 | D36: =[1]종목!D36 -> 10월 | E36: =(C36-C35)/C35 -> -0.58042813 | G36: =[1]종목!G36 -> 2022 | H36: =[1]종목!$H36 -> 499500 | I36: =[1]종목!I36 -> 11월 | J36: =(H36-H35)/H35 -> -0.48558187 | L36: =[1]종목!L36 -> 2022 | M36: =[1]종목!$M36 -> 134303 | N36: =[1]종목!N36 -> 10월 | O36: =(M36-M35)/M35 -> -0.75036617
B37: =[1]종목!B37 -> 2023 | C37: =[1]종목!$C37 -> 130000 | D37: =[1]종목!D37 -> 7월 | E37: =(C37-C36)/C36 -> 0.89504373 | G37: =[1]종목!G37 -> 2023 | H37: =[1]종목!$H37 -> 590000 | I37: =[1]종목!I37 -> 5월 | J37: =(H37-H36)/H36 -> 0.18118118 | L37: =[1]종목!L37 -> 2023 | M37: =[1]종목!$M37 -> 189700 | N37: =[1]종목!N37 -> 6월 | O37: =(M37-M36)/M36 -> 0.41247776
B38: =[1]종목!B38 -> 2024 | C38: =[1]종목!$C38 -> 219000 | D38: =[1]종목!D38 -> 12월 | E38: =(C38-C37)/C37 -> 0.68461538 | G38: =[1]종목!G38 -> 2024 | H38: =[1]종목!$H38 -> 300000 | I38: =[1]종목!I38 -> 2월 | J38: =(H38-H37)/H37 -> -0.49152542 | L38: =[1]종목!L38 -> 2024 | M38: =[1]종목!$M38 -> 62200 | N38: =[1]종목!N38 -> 12월 | O38: =(M38-M37)/M37 -> -0.67211386
B39: =[1]종목!B39 -> 2025 | C39: =[1]종목!$C39 -> 994500 | D39: =[1]종목!D39 -> 11월 | E39: =(C39-C38)/C38 -> 3.5410959 | G39: =[1]종목!G39 -> 2025 | H39: 300000 | I39: =[1]종목!I39 -> 12월 | J39: =(H39-H38)/H38 -> 0 | L39: =[1]종목!L39 -> 2025 | M39: =[1]종목!$M39 -> 51800 | N39: =[1]종목!N39 -> 2월 | O39: =(M39-M38)/M38 -> -0.16720257
B41: J 식품 | C41: 주가 | D41: KT&G | E41: 등락률
B42: =[1]종목!B42 -> 2015 | C42: =[1]종목!$C42 -> 120500 | D42: =[1]종목!D42 -> 10월
B43: =[1]종목!B43 -> 2016 | C43: =[1]종목!$C43 -> 139500 | D43: =[1]종목!D43 -> 7월 | E43: =(C43-C42)/C42 -> 0.15767635
B44: =[1]종목!B44 -> 2017 | C44: =[1]종목!$C44 -> 94900 | D44: =[1]종목!D44 -> 3월 | E44: =(C44-C43)/C43 -> -0.31971326
...
